Workbook
Name Machine: Dashboard!$J$5

Sheet Dashboard
B1: Production Performance Dashboard
D4: Productivity | J4: Downtime | P4: Running Hour
J5: BRDR5
D21: Average Running Hour | J21: Trouble Machine | P21: Trouble Type

Sheet Calculation
A1: Machine | B1: Productivity | H1: Machine | I1: Downtime | O1: Machine | P1: Total Running Hour | V1: Machine | W1: Average Running Hour
A2: BRDR1 | B2: {=AVERAGE(IF((Table4[Machine]=A2),Table4[Productivity]))} -> 1.1772723 | C2: {=_xlfn._xlws.SORT(A2:B10,2,1)} -> BRDR4 | D2: 1.1487275 | E2: =IF($C2<>Machine,$D2,NA()) -> 1.1487275 | F2: =IF($C2=Machine,$D2,NA()) -> #N/A | H2: BRDR1 | I2: {=AVERAGE(IF((Table4[Machine]=H2),Table4[Downtime]))} -> 0.089444444 | J2: {=_xlfn._xlws.SORT(H2:I10,2,1)} -> BRDR3 | K2: 0.020833333 | L2: =IF($J2<>Machine,$K2,NA()) -> 0.020833333 | M2: =IF($J2=Machine,$K2,NA()) -> #N/A | O2: BRDR1 | P2: {=AVERAGE(IF((Table4[Machine]=Calculation!$O2),Table4[Total Running Hour]))} -> 0.098509259 | Q2: {=_xlfn._xlws.SORT(O2:P10,2,1)} -> BRDR8 | R2: 0.097143519 | S2: =IF($Q2<>Machine,$R2,NA()) -> 0.097143519 | T2: =IF($Q2=Machine,$R2,NA()) -> #N/A | V2: BRDR1 | W2: {=AVERAGE(IF((Table4[Machine]=Calculation!$O2),Table4[Average Running Hour]))} -> 0.36940972 | X2: {=_xlfn._xlws.SORT(V2:W10,2,1)} -> BRDR8 | Y2: 0.36428819 | Z2: =IF($X2<>Machine,$Y2,NA()) -> 0.36428819 | AA2: =IF($X2=Machine,$Y2,NA()) -> #N/A
A3: BRDR2 | B3: {=AVERAGE(IF((Table4[Machine]=A3),Table4[Productivity]))} -> 1.1623565 | C3: BRDR2 | D3: 1.1623565 | E3: =IF($C3<>Machine,$D3,NA()) -> 1.1623565 | F3: =IF($C3=Machine,$D3,NA()) -> #N/A | H3: BRDR2 | I3: {=AVERAGE(IF((Table4[Machine]=H3),Table4[Downtime]))} -> 0.049444444 | J3: BRDR2 | K3: 0.049444444 | L3: =IF($J3<>Machine,$K3,NA()) -> 0.049444444 | M3: =IF($J3=Machine,$K3,NA()) -> #N/A | O3: BRDR2 | P3: {=AVERAGE(IF((Table4[Machine]=Calculation!$O3),Table4[Total Running Hour]))} -> 0.099175926 | Q3: BRDR9 | R3: 0.097328704 | S3: =IF($Q3<>Machine,$R3,NA()) -> 0.097328704 | T3: =IF($Q3=Machine,$R3,NA()) -> #N/A | V3: BRDR2 | W3: {=AVERAGE(IF((Table4[Machine]=Calculation!$O3),Table4[Average Running Hour]))} -> 0.37190972 | X3: BRDR9 | Y3: 0.36498264 | Z3: =IF($X3<>Machine,$Y3,NA()) -> 0.36498264 | AA3: =IF($X3=Machine,$Y3,NA()) -> #N/A
A4: BRDR3 | B4: {=AVERAGE(IF((Table4[Machine]=A4),Table4[Productivity]))} -> 1.1707317 | C4: BRDR3 | D4: 1.1707317 | E4: =IF($C4<>Machine,$D4,NA()) -> 1.1707317 | F4: =IF($C4=Machine,$D4,NA()) -> #N/A | H4: BRDR3 | I4: {=AVERAGE(IF((Table4[Machine]=H4),Table4[Downtime]))} -> 0.020833333 | J4: BRDR4 | K4: 0.051388889 | L4: =IF($J4<>Machine,$K4,NA()) -> 0.051388889 | M4: =IF($J4=Machine,$K4,NA()) -> #N/A | O4: BRDR3 | P4: {=AVERAGE(IF((Table4[Machine]=Calculation!$O4),Table4[Total Running Hour]))} -> 0.099652778 | Q4: BRDR1 | R4: 0.098509259 | S4: =IF($Q4<>Machine,$R4,NA()) -> 0.098509259 | T4: =IF($Q4=Machine,$R4,NA()) -> #N/A | V4: BRDR3 | W4: {=AVERAGE(IF((Table4[Machine]=Calculation!$O4),Table4[Average Running Hour]))} -> 0.37369792 | X4: BRDR1 | Y4: 0.36940972 | Z4: =IF($X4<>Machine,$Y4,NA()) -> 0.36940972 | AA4: =IF($X4=Machine,$Y4,NA()) -> #N/A
A5: BRDR4 | B5: {=AVERAGE(IF((Table4[Machine]=A5),Table4[Productivity]))} -> 1.1487275 | C5: BRDR1 | D5: 1.1772723 | E5: =IF($C5<>Machine,$D5,NA()) -> 1.1772723 | F5: =IF($C5=Machine,$D5,NA()) -> #N/A | H5: BRDR4 | I5: {=AVERAGE(IF((Table4[Machine]=H5),Table4[Downtime]))} -> 0.051388889 | J5: BRDR6 | K5: 0.068333333 | L5: =IF($J5<>Machine,$K5,NA()) -> 0.068333333 | M5: =IF($J5=Machine,$K5,NA()) -> #N/A | O5: BRDR4 | P5: {=AVERAGE(IF((Table4[Machine]=Calculation!$O5),Table4[Total Running Hour]))} -> 0.099143519 | Q5: BRDR7 | R5: 0.098583333 | S5: =IF($Q5<>Machine,$R5,NA()) -> 0.098583333 | T5: =IF($Q5=Machine,$R5,NA()) -> #N/A | V5: BRDR4 | W5: {=AVERAGE(IF((Table4[Machine]=Calculation!$O5),Table4[Average Running Hour]))} -> 0.37178819 | X5: BRDR7 | Y5: 0.3696875 | Z5: =IF($X5<>Machine,$Y5,NA()) -> 0.3696875 | AA5: =IF($X5=Machine,$Y5,NA()) -> #N/A
A6: BRDR5 | B6: {=AVERAGE(IF((Table4[Machine]=A6),Table4[Productivity]))} -> 1.1967898 | C6: BRDR9 | D6: 1.1844171 | E6: =IF($C6<>Machine,$D6,NA()) -> 1.1844171 | F6: =IF($C6=Machine,$D6,NA()) -> #N/A | H6: BRDR5 | I6: {=AVERAGE(IF((Table4[Machine]=H6),Table4[Downtime]))} -> 0.081388889 | J6: BRDR5 | K6: 0.081388889 | L6: =IF($J6<>Machine,$K6,NA()) -> #N/A | M6: =IF($J6=Machine,$K6,NA()) -> 0.081388889 | O6: BRDR5 | P6: {=AVERAGE(IF((Table4[Machine]=Calculation!$O6),Table4[Total Running Hour]))} -> 0.098643519 | Q6: BRDR5 | R6: 0.098643519 | S6: =IF($Q6<>Machine,$R6,NA()) -> #N/A | T6: =IF($Q6=Machine,$R6,NA()) -> 0.098643519 | V6: BRDR5 | W6: {=AVERAGE(IF((Table4[Machine]=Calculation!$O6),Table4[Average Running Hour]))} -> 0.36991319 | X6: BRDR5 | Y6: 0.36991319 | Z6: =IF($X6<>Machine,$Y6,NA()) -> #N/A | AA6: =IF($X6=Machine,$Y6,NA()) -> 0.36991319
A7: BRDR6 | B7: {=AVERAGE(IF((Table4[Machine]=A7),Table4[Productivity]))} -> 1.1941557 | C7: BRDR6 | D7: 1.1941557 | E7: =IF($C7<>Machine,$D7,NA()) -> 1.1941557 | F7: =IF($C7=Machine,$D7,NA()) -> #N/A | H7: BRDR6 | I7: {=AVERAGE(IF((Table4[Machine]=H7),Table4[Downtime]))} -> 0.068333333 | J7: BRDR7 | K7: 0.085 | L7: =IF($J7<>Machine,$K7,NA()) -> 0.085 | M7: =IF($J7=Machine,$K7,NA()) -> #N/A | O7: BRDR6 | P7: {=AVERAGE(IF((Table4[Machine]=Calculation!$O7),Table4[Total Running Hour]))} -> 0.098861111 | Q7: BRDR6 | R7: 0.098861111 | S7: =IF($Q7<>Machine,$R7,NA()) -> 0.098861111 | T7: =IF($Q7=Machine,$R7,NA()) -> #N/A | V7: BRDR6 | W7: {=AVERAGE(IF((Table4[Machine]=Calculation!$O7),Table4[Average Running Hour]))} -> 0.37072917 | X7: BRDR6 | Y7: 0.37072917 | Z7: =IF($X7<>Machine,$Y7,NA()) -> 0.37072917 | AA7: =IF($X7=Machine,$Y7,NA()) -> #N/A
A8: BRDR7 | B8: {=AVERAGE(IF((Table4[Machine]=A8),Table4[Productivity]))} -> 1.2045647 | C8: BRDR5 | D8: 1.1967898 | E8: =IF($C8<>Machine,$D8,NA()) -> #N/A | F8: =IF($C8=Machine,$D8,NA()) -> 1.1967898 | H8: BRDR7 | I8: {=AVERAGE(IF((Table4[Machine]=H8),Table4[Downtime]))} -> 0.085 | J8: BRDR1 | K8: 0.089444444 | L8: =IF($J8<>Machine,$K8,NA()) -> 0.089444444 | M8: =IF($J8=Machine,$K8,NA()) -> #N/A | O8: BRDR7 | P8: {=AVERAGE(IF((Table4[Machine]=Calculation!$O8),Table4[Total Running Hour]))} -> 0.098583333 | Q8: BRDR4 | R8: 0.099143519 | S8: =IF($Q8<>Machine,$R8,NA()) -> 0.099143519 | T8: =IF($Q8=Machine,$R8,NA()) -> #N/A | V8: BRDR7 | W8: {=AVERAGE(IF((Table4[Machine]=Calculation!$O8),Table4[Average Running Hour]))} -> 0.3696875 | X8: BRDR4 | Y8: 0.37178819 | Z8: =IF($X8<>Machine,$Y8,NA()) -> 0.37178819 | AA8: =IF($X8=Machine,$Y8,NA()) -> #N/A
A9: BRDR8 | B9: {=AVERAGE(IF((Table4[Machine]=A9),Table4[Productivity]))} -> 1.2367154 | C9: BRDR7 | D9: 1.2045647 | E9: =IF($C9<>Machine,$D9,NA()) -> 1.2045647 | F9: =IF($C9=Machine,$D9,NA()) -> #N/A | H9: BRDR8 | I9: {=AVERAGE(IF((Table4[Machine]=H9),Table4[Downtime]))} -> 0.17138889 | J9: BRDR9 | K9: 0.16027778 | L9: =IF($J9<>Machine,$K9,NA()) -> 0.16027778 | M9: =IF($J9=Machine,$K9,NA()) -> #N/A | O9: BRDR8 | P9: {=AVERAGE(IF((Table4[Machine]=Calculation!$O9),Table4[Total Running Hour]))} -> 0.097143519 | Q9: BRDR2 | R9: 0.099175926 | S9: =IF($Q9<>Machine,$R9,NA()) -> 0.099175926 | T9: =IF($Q9=Machine,$R9,NA()) -> #N/A | V9: BRDR8 | W9: {=AVERAGE(IF((Table4[Machine]=Calculation!$O9),Table4[Average Running Hour]))} -> 0.36428819 | X9: BRDR2 | Y9: 0.37190972 | Z9: =IF($X9<>Machine,$Y9,NA()) -> 0.37190972 | AA9: =IF($X9=Machine,$Y9,NA()) -> #N/A
A10: BRDR9 | B10: {=AVERAGE(IF((Table4[Machine]=A10),Table4[Productivity]))} -> 1.1844171 | C10: BRDR8 | D10: 1.2367154 | E10: =IF($C10<>Machine,$D10,NA()) -> 1.2367154 | F10: =IF($C10=Machine,$D10,NA()) -> #N/A | H10: BRDR9 | I10: {=AVERAGE(IF((Table4[Machine]=H10),Table4[Downtime]))} -> 0.16027778 | J10: BRDR8 | K10: 0.17138889 | L10: =IF($J10<>Machine,$K10,NA()) -> 0.17138889 | M10: =IF($J10=Machine,$K10,NA()) -> #N/A | O10: BRDR9 | P10: {=AVERAGE(IF((Table4[Machine]=Calculation!$O10),Table4[Total Running Hour]))} -> 0.097328704 | Q10: BRDR3 | R10: 0.099652778 | S10: =IF($Q10<>Machine,$R10,NA()) -> 0.099652778 | T10: =IF($Q10=Machine,$R10,NA()) -> #N/A | V10: BRDR9 | W10: {=AVERAGE(IF((Table4[Machine]=Calculation!$O10),Table4[Average Running Hour]))} -> 0.36498264 | X10: BRDR3 | Y10: 0.37369792 | Z10: =IF($X10<>Machine,$Y10,NA()) -> 0.37369792 | AA10: =IF($X10=Machine,$Y10,NA()) -> #N/A
I13: Trouble Type Frequency
A14: Machine | B14: Frequency Trouble | H14: Machine | I14: Jarum patah | J14: Bundet Bawah | K14: Bundet Atas | L14: Benang Putus | M14: Sensor Lepas | N14: Mesin mati
A15: BRDR1 | B15: {=COUNT(IF((Table5[Machine]=A15)*(Table5[Downtime]<>0),Table5[Downtime]))} -> 5 | C15: {=_xlfn._xlws.SORT($A$15:$B$23,2,1)} -> BRDR2 | D15: 2 | E15: =IF($C15<>Machine,$D15,NA()) -> 2 | F15: =IF($C15=Machine,$D15,NA()) -> #N/A | H15: BRDR1 | I15: {=COUNTIFS(Table5[Machine],Calculation!H15,Table5[Downtime Cause],Calculation!$I$14:$N$14,Table5[Downtime],"<>0")} -> 1 | J15: 0 | K15: 4 | L15: 0 | M15: 0 | N15: 0 | P15: Jarum patah | Q15: =I25 -> 2 | S15: {=_xlfn._xlws.SORT(P15:Q20,2,1)} -> Jarum patah | T15: 2
A16: BRDR2 | B16: {=COUNT(IF((Table5[Machine]=A16)*(Table5[Downtime]<>0),Table5[Downtime]))} -> 2 | C16: BRDR3 | D16: 2 | E16: =IF($C16<>Machine,$D16,NA()) -> 2 | F16: =IF($C16=Machine,$D16,NA()) -> #N/A | H16: BRDR2 | I16: {=COUNTIFS(Table5[Machine],Calculation!H16,Table5[Downtime Cause],Calculation!$I$14:$N$14,Table5[Downtime],"<>0")} -> 0 | J16: 0 | K16: 1 | L16: 1 | M16: 0 | N16: 0 | P16: Bundet Bawah | Q16: =J25 -> 7 | S16: Sensor Lepas | T16: 2
A17: BRDR3 | B17: {=COUNT(IF((Table5[Machine]=A17)*(Table5[Downtime]<>0),Table5[Downtime]))} -> 2 | C17: BRDR4 | D17: 3 | E17: =IF($C17<>Machine,$D17,NA()) -> 3 | F17: =IF($C17=Machine,$D17,NA()) -> #N/A | H17: BRDR3 | I17: {=COUNTIFS(Table5[Machine],Calculation!H17,Table5[Downtime Cause],Calculation!$I$14:$N$14,Table5[Downtime],"<>0")} -> 0 | J17: 1 | K17: 0 | L17: 1 | M17: 0 | N17: 0 | P17: Bundet Atas | Q17: =K25 -> 13 | S17: Benang Putus | T17: 4
A18: BRDR4 | B18: {=COUNT(IF((Table5[Machine]=A18)*(Table5[Downtime]<>0),Table5[Downtime]))} -> 3 | C18: BRDR6 | D18: 3 | E18: =IF($C18<>Machine,$D18,NA()) -> 3 | F18: =IF($C18=Machine,$D18,NA()) -> #N/A | H18: BRDR4 | I18: {=COUNTIFS(Table5[Machine],Calculation!H18,Table5[Downtime Cause],Calculation!$I$14:$N$14,Table5[Downtime],"<>0")} -> 0 | J18: 0 | K18: 1 | L18: 0 | M18: 1 | N18: 1 | P18: Benang Putus | Q18: =L25 -> 4 | S18: Bundet Bawah | T18: 7
A19: BRDR5 | B19: {=COUNT(IF((Table5[Machine]=A19)*(Table5[Downtime]<>0),Table5[Downtime]))} -> 5 | C19: BRDR7 | D19: 3 | E19: =IF($C19<>Machine,$D19,NA()) -> 3 | F19: =IF($C19=Machine,$D19,NA()) -> #N/A | H19: BRDR5 | I19: {=COUNTIFS(Table5[Machine],Calculation!H19,Table5[Downtime Cause],Calculation!$I$14:$N$14,Table5[Downtime],"<>0")} -> 0 | J19: 2 | K19: 1 | L19: 1 | M19: 0 | N19: 1 | P19: Sensor Lepas | Q19: =M25 -> 2 | S19: Mesin mati | T19: 9
A20: BRDR6 | B20: {=COUNT(IF((Table5[Machine]=A20)*(Table5[Downtime]<>0),Table5[Downtime]))} -> 3 | C20: BRDR1 | D20: 5 | E20: =IF($C20<>Machine,$D20,NA()) -> 5 | F20: =IF($C20=Machine,$D20,NA()) -> #N/A | H20: BRDR6 | I20: {=COUNTIFS(Table5[Machine],Calculation!H20,Table5[Downtime Cause],Calculation!$I$14:$N$14,Table5[Downtime],"<>0")} -> 0 | J20: 0 | K20: 0 | L20: 0 | M20: 0 | N20: 3 | P20: Mesin mati | Q20: =N25 -> 9 | S20: Bundet Atas | T20: 13
A21: BRDR7 | B21: {=COUNT(IF((Table5[Machine]=A21)*(Table5[Downtime]<>0),Table5[Downtime]))} -> 3 | C21: BRDR5 | D21: 5 | E21: =IF($C21<>Machine,$D21,NA()) -> #N/A | F21: =IF($C21=Machine,$D21,NA()) -> 5 | H21: BRDR7 | I21: {=COUNTIFS(Table5[Machine],Calculation!H21,Table5[Downtime Cause],Calculation!$I$14:$N$14,Table5[Downtime],"<>0")} -> 0 | J21: 2 | K21: 1 | L21: 0 | M21: 0 | N21: 0
A22: BRDR8 | B22: {=COUNT(IF((Table5[Machine]=A22)*(Table5[Downtime]<>0),Table5[Downtime]))} -> 7 | C22: BRDR8 | D22: 7 | E22: =IF($C22<>Machine,$D22,NA()) -> 7 | F22: =IF($C22=Machine,$D22,NA()) -> #N/A | H22: BRDR8 | I22: {=COUNTIFS(Table5[Machine],Calculation!H22,Table5[Downtime Cause],Calculation!$I$14:$N$14,Table5[Downtime],"<>0")} -> 1 | J22: 1 | K22: 3 | L22: 0 | M22: 0 | N22: 2
A23: BRDR9 | B23: {=COUNT(IF((Table5[Machine]=A23)*(Table5[Downtime]<>0),Table5[Downtime]))} -> 7 | C23: BRDR9 | D23: 7 | E23: =IF($C23<>Machine,$D23,NA()) -> 7 | F23: =IF($C23=Machine,$D23,NA()) -> #N/A | H23: BRDR9 | I23: {=COUNTIFS(Table5[Machine],Calculation!H23,Table5[Downtime Cause],Calculation!$I$14:$N$14,Table5[Downtime],"<>0")} -> 0 | J23: 1 | K23: 2 | L23: 1 | M23: 1 | N23: 2
H25: Total | I25: =SUM(I15:I24) -> 2 | J25: =SUM(J15:J24) -> 7 | K25: =SUM(K15:K24) -> 13 | L25: =SUM(L15:L24) -> 4 | M25: =SUM(M15:M24) -> 2 | N25: =SUM(N15:N24) -> 9
C27: {=COUNT(IF((Table4[Machine]=Calculation!$H15)*(Table4[Downtime]<>0),#REF!,NA()))} -> 0
C28: {=COUNT(IF((Table4[Machine]=Calculation!$H16)*(Table4[Downtime]<>0)*(ISNUMBER(SEARCH(I16:I25,#REF!))),#REF!))} -> 0
C29: {=COUNT(IF((Table4[Machine]=Calculation!$H17)*(Table4[Downtime]<>0)*(ISNUMBER(SEARCH(I17:I26,#REF!))),#REF!))} -> 0
C30: {=COUNT(IF((Table4[Machine]=Calculation!$H18)*(Table4[Downtime]<>0)*(ISNUMBER(SEARCH(I18:I27,#REF!))),#REF!))} -> 0
C31: {=COUNT(IF((Table4[Machine]=Calculation!$H19)*(Table4[Downtime]<>0)*(ISNUMBER(SEARCH(I19:I28,#REF!))),#REF!))} -> 0
C32: {=COUNT(IF((Table4[Machine]=Calculation!$H20)*(Table4[Downtime]<>0)*(ISNUMBER(SEARCH(I20:I29,#REF!))),#REF!))} -> 0
C33: {=COUNT(IF((Table4[Machine]=Calculation!$H21)*(Table4[Downtime]<>0)*(ISNUMBER(SEARCH(I21:I30,#REF!))),#REF!))} -> 0
C34: {=COUNT(IF((Table4[Machine]=Calculation!$H22)*(Table4[Downtime]<>0)*(ISNUMBER(SEARCH(I22:I31,#REF!))),#REF!))} -> 0
C35: {=COUNT(IF((Table4[Machine]=Calculation!$H23)*(Table4[Downtime]<>0)*(ISNUMBER(SEARCH(I23:I32,#REF!))),#REF!))} -> 0
C36: {=COUNT(IF((Table4[Machine]=Calculation!$H24)*(Table4[Downtime]<>0)*(ISNUMBER(SEARCH(I24:I33,#REF!))),#REF!))} -> 0

Sheet MachinePerformance Accumulation
A1: Machine | B1: Start | C1: Stop | D1: Downtime | E1: Total Running Hour | F1: Average Running Hour | G1: Product | H1: Productivity
A2: BRDR1 | B2: 0.33333333 | C2: 0.70833333 | D2: {=SUM(IF((Table4[[#This Row],[Machine]]=Table5[Machine]),Table5[Downtime]))} -> 0.089444444 | E2: ='Daily Performance Monitoring '!BF4 -> 0.098509259 | F2: ='Daily Performance Monitoring '!BG4 -> 0.36940972 | G2: ='Daily Performance Monitoring '!BH4 -> 167 | H2: =Table4[[#This Row],[Product]]/Table4[[#This Row],[Total Running Hour]]/1440 -> 1.1772723
A3: BRDR2 | B3: 0.33333333 | C3: 0.70833333 | D3: {=SUM(IF((Table4[[#This Row],[Machine]]=Table5[Machine]),Table5[Downtime]))} -> 0.049444444 | E3: ='Daily Performance Monitoring '!BF5 -> 0.099175926 | F3: ='Daily Performance Monitoring '!BG5 -> 0.37190972 | G3: ='Daily Performance Monitoring '!BH5 -> 166 | H3: =Table4[[#This Row],[Product]]/Table4[[#This Row],[Total Running Hour]]/1440 -> 1.1623565
A4: BRDR3 | B4: 0.33333333 | C4: 0.70833333 | D4: {=SUM(IF((Table4[[#This Row],[Machine]]=Table5[Machine]),Table5[Downtime]))} -> 0.020833333 | E4: ='Daily Performance Monitoring '!BF6 -> 0.099652778 | F4: ='Daily Performance Monitoring '!BG6 -> 0.37369792 | G4: ='Daily Performance Monitoring '!BH6 -> 168 | H4: =Table4[[#This Row],[Product]]/Table4[[#This Row],[Total Running Hour]]/1440 -> 1.1707317
A5: BRDR4 | B5: 0.33333333 | C5: 0.70833333 | D5: {=SUM(IF((Table4[[#This Row],[Machine]]=Table5[Machine]),Table5[Downtime]))} -> 0.051388889 | E5: ='Daily Performance Monitoring '!BF7 -> 0.099143519 | F5: ='Daily Performance Monitoring '!BG7 -> 0.37178819 | G5: ='Daily Performance Monitoring '!BH7 -> 164 | H5: =Table4[[#This Row],[Product]]/Table4[[#This Row],[Total Running Hour]]/1440 -> 1.1487275
A6: BRDR5 | B6: 0.33333333 | C6: 0.70833333 | D6: {=SUM(IF((Table4[[#This Row],[Machine]]=Table5[Machine]),Table5[Downtime]))} -> 0.081388889 | E6: ='Daily Performance Monitoring '!BF8 -> 0.098643519 | F6: ='Daily Performance Monitoring '!BG8 -> 0.36991319 | G6: ='Daily Performance Monitoring '!BH8 -> 170 | H6: =Table4[[#This Row],[Product]]/Table4[[#This Row],[Total Running Hour]]/1440 -> 1.1967898
A7: BRDR6 | B7: 0.33333333 | C7: 0.70833333 | D7: {=SUM(IF((Table4[[#This Row],[Machine]]=Table5[Machine]),Table5[Downtime]))} -> 0.068333333 | E7: ='Daily Performance Monitoring '!BF9 -> 0.098861111 | F7: ='Daily Performance Monitoring '!BG9 -> 0.37072917 | G7: ='Daily Performance Monitoring '!BH9 -> 170 | H7: =Table4[[#This Row],[Product]]/Table4[[#This Row],[Total Running Hour]]/1440 -> 1.1941557
A8: BRDR7 | B8: 0.33333333 | C8: 0.70833333 | D8: {=SUM(IF((Table4[[#This Row],[Machine]]=Table5[Machine]),Table5[Downtime]))} -> 0.085 | E8: ='Daily Performance Monitoring '!BF10 -> 0.098583333 | F8: ='Daily Performance Monitoring '!BG10 -> 0.3696875 | G8: ='Daily Performance Monitoring '!BH10 -> 171 | H8: =Table4[[#This Row],[Product]]/Table4[[#This Row],[Total Running Hour]]/1440 -> 1.2045647
A9: BRDR8 | B9: 0.33333333 | C9: 0.70833333 | D9: {=SUM(IF((Table4[[#This Row],[Machine]]=Table5[Machine]),Table5[Downtime]))} -> 0.17138889 | E9: ='Daily Performance Monitoring '!BF11 -> 0.097143519 | F9: ='Daily Performance Monitoring '!BG11 -> 0.36428819 | G9: ='Daily Performance Monitoring '!BH11 -> 173 | H9: =Table4[[#This Row],[Product]]/Table4[[#This Row],[Total Running Hour]]/1440 -> 1.2367154
A10: BRDR9 | B10: 0.33333333 | C10: 0.70833333 | D10: {=SUM(IF((Table4[[#This Row],[Machine]]=Table5[Machine]),Table5[Downtime]))} -> 0.16027778 | E10: ='Daily Performance Monitoring '!BF12 -> 0.097328704 | F10: ='Daily Performance Monitoring '!BG12 -> 0.36498264 | G10: ='Daily Performance Monitoring '!BH12 -> 166 | H10: =Table4[[#This Row],[Product]]/Table4[[#This Row],[Total Running Hour]]/1440 -> 1.1844171

Sheet Daily Performance Monitoring 
A1: TanggaK Produksi | B1: Mesin | C1: CoKumn1 | D1: CoKumn2 | E1: CoKumn3 | F1: CoKumn4 | G1: CoKumn5 | H1: CoKumn6 | I1: CoKumn7 | J1: CoKumn8 | K1: CoKumn9 | L1: CoKumn10 | M1: CoKumn11 | N1: CoKumn12 | O1: CoKumn13 | P1: CoKumn14 | Q1: CoKumn15 | R1: CoKumn16 | S1: CoKumn17 | T1: CoKumn18 | U1: CoKumn19 | V1: CoKumn20 | W1: CoKumn21 | X1: CoKumn22 | Y1: CoKumn23 | Z1: CoKumn24 | AA1: CoKumn25 | AB1: CoKumn26 | AC1: CoKumn27 | AD1: CoKumn28 | AE1: CoKumn29 | AF1: CoKumn30 | AG1: CoKumn31 | AH1: CoKumn32 | AI1: CoKumn33 | AJ1: CoKumn34 | AK1: CoKumn35 | AL1: CoKumn36 | AM1: CoKumn37 | AN1: CoKumn38 | AO1: CoKumn39 | AP1: CoKumn40 | AQ1: CoKumn41 | AR1: CoKumn42 | AS1: CoKumn43 | AT1: CoKumn44 | AU1: CoKumn45 | AV1: CoKumn46 | AW1: CoKumn47 | AX1: CoKumn48 | AY1: CoKumn49 | AZ1: CoKumn50 | BA1: CoKumn51 | BB1: CoKumn52 | BC1: CoKumn53
B2: BRDR1 | H2: BRDR2 | N2: BRDR3 | T2: BRDR4 | Z2: BRDR5 | AF2: BRDR6 | AL2: BRDR7 | AR2: BRDR8 | AX2: BRDR9
B3: Start | C3: Stop | D3: Downtime (mins) | E3: Running Time (hours) | F3: Product (pcs) | G3: Productivity (pcs/hour) | H3: Start | I3: Stop | J3: Downtime (mins) | K3: Running Time (hours) | L3: Product (pcs) | M3: Productivity (pcs/hour) | N3: Start | O3: Stop | P3: Downtime (mins) | Q3: Running Time (hours) | R3: Product (pcs) | S3: Productivity (pcs/hour) | T3: Start | U3: Stop | V3: Downtime (mins) | W3: Running Time (hours) | X3: Product (pcs) | Y3: Productivity (pcs/hour) | Z3: Start | AA3: Stop | AB3: Downtime (mins) | AC3: Running Time (hours) | AD3: Product (pcs) | AE3: Productivity (pcs/hour) | AF3: Start | AG3: Stop | AH3: Downtime (mins) | AI3: Running Time (hours) | AJ3: Product (pcs) | AK3: Productivity (pcs/hour) | AL3: Start | AM3: Stop | AN3: Downtime (mins) | AO3: Running Time (hours) | AP3: Product (pcs) | AQ3: Productivity (pcs/hour) | AR3: Start | AS3: Stop | AT3: Downtime (mins) | AU3: Running Time (hours) | AV3: Product (pcs) | AW3: Productivity (pcs/hour) | AX3: Start | AY3: Stop | AZ3: Downtime (mins) | BA3: Running Time (hours) | BB3: Product (pcs) | BC3: Productivity (pcs/hour) | BE3: Machine | BF3: TotaK Running Hour | BG3: Average Running Hour | BH3: Product (pcs) | BI3: Productivity (pcs/hour)
A4: 45901 | B4: 0.33333333 | C4: 0.70833333 | D4: {=SUM(IF((Table3[[#This Row],[TanggaK Produksi]]=Table5[Date])*('Daily Performance Monitoring '!$B$2=Table5[Machine]),Table5[Downtime]))} -> 0.020833333 | E4: =C4-B4-D4 -> 0.35416667 | F4: 9 | G4: =F4/E4/24 -> 1.0588235 | H4: 0.33333333 | I4: 0.70833333 | J4: {=SUM(IF((Table3[[#This Row],[TanggaK Produksi]]=Table5[Date])*('Daily Performance Monitoring '!$H$2=Table5[Machine]),Table5[Downtime]))} -> 0.013888889 | K4: =I4-H4-J4 -> 0.36111111 | L4: 11 | M4: =L4/K4/24 -> 1.2692308 | N4: 0.33333333 | O4: 0.70833333 | P4: {=SUM(IF((Table3[[#This Row],[TanggaK Produksi]]=Table5[Date])*('Daily Performance Monitoring '!$N$2=Table5[Machine]),Table5[Downtime]))} -> 0 | Q4: =O4-N4-P4 -> 0.375 | R4: 9 | S4: =R4/Q4/24 -> 1 | T4: 0.33333333 | U4: 0.70833333 | V4: {=SUM(IF((Table3[[#This Row],[TanggaK Produksi]]=Table5[Date])*('Daily Performance Monitoring '!$T$2=Table5[Machine]),Table5[Downtime]))} -> 0 | W4: =U4-T4-V4 -> 0.375 | X4: 12 | Y4: =X4/W4/24 -> 1.3333333 | Z4: 0.33333333 | AA4: 0.70833333 | AB4: {=SUM(IF((Table3[[#This Row],[TanggaK Produksi]]=Table5[Date])*('Daily Performance Monitoring '!$Z$2=Table5[Machine]),Table5[Downtime]))} -> 0 | AC4: =AA4-Z4-AB4 -> 0.375 | AD4: 11 | AE4: =AD4/AC4/24 -> 1.2222222 | AF4: 0.33333333 | AG4: 0.70833333 | AH4: {=SUM(IF((Table3[[#This Row],[TanggaK Produksi]]=Table5[Date])*('Daily Performance Monitoring '!$AF$2=Table5[Machine]),Table5[Downtime]))} -> 0 | AI4: =AG4-AF4-AH4 -> 0.375 | AJ4: 11 | AK4: =AJ4/AI4/24 -> 1.2222222 | AL4: 0.33333333 | AM4: 0.70833333 | AN4: {=SUM(IF((Table3[[#This Row],[TanggaK Produksi]]=Table5[Date])*('Daily Performance Monitoring '!$AL$2=Table5[Machine]),Table5[Downtime]))} -> 0 | AO4: =AM4-AL4-AN4 -> 0.375 | AP4: 10 | AQ4: =AP4/AO4/24 -> 1.1111111 | AR4: 0.33333333 | AS4: 0.70833333 | AT4: {=SUM(IF((Table3[[#This Row],[TanggaK Produksi]]=Table5[Date])*('Daily Performance Monitoring '!$AR$2=Table5[Machine]),Table5[Downtime]))} -> 0 | AU4: =AS4-AR4-AT4 -> 0.375 | AV4: 12 | AW4: =AV4/AU4/24 -> 1.3333333 | AX4: 0.33333333 | AY4: 0.70833333 | AZ4: {=SUM(IF((Table3[[#This Row],[TanggaK Produksi]]=Table5[Date])*('Daily Performance Monitoring '!$AX$2=Table5[Machine]),Table5[Downtime]))} -> 0 | BA4: =AY4-AX4-AZ4 -> 0.375 | BB4: 10 | BC4: =BB4/BA4/24 -> 1.1111111 | BE4: BRDR1 | BF4: =E20 -> 0.098509259 | BG4: =AVERAGE(E4:E19) -> 0.36940972 | BH4: =F20 -> 167 | BI4: =G20 -> 1.1772723
A5: 45902 | B5: 0.33333333 | C5: 0.70833333 | D5: {=SUM(IF((Table3[[#This Row],[TanggaK Produksi]]=Table5[Date])*('Daily Performance Monitoring '!$B$2=Table5[Machine]),Table5[Downtime]))} -> 0 | E5: =C5-B5-D5 -> 0.375 | F5: 9 | G5: =F5/E5/24 -> 1 | H5: 0.33333333 | I5: 0.70833333 | J5: {=SUM(IF((Table3[[#This Row],[TanggaK Produksi]]=Table5[Date])*('Daily Performance Monitoring '!$H$2=Table5[Machine]),Table5[Downtime]))} -> 0 | K5: =I5-H5-J5 -> 0.375 | L5: 10 | M5: =L5/K5/24 -> 1.1111111 | N5: 0.33333333 | O5: 0.70833333 | P5: {=SUM(IF((Table3[[#This Row],[TanggaK Produksi]]=Table5[Date])*('Daily Performance Monitoring '!$N$2=Table5[Machine]),Table5[Downtime]))} -> 0 | Q5: =O5-N5-P5 -> 0.375 | R5: 11 | S5: =R5/Q5/24 -> 1.2222222 | T5: 0.33333333 | U5: 0.70833333 | V5: {=SUM(IF((Table3[[#This Row],[TanggaK Produksi]]=Table5[Date])*('Daily Performance Monitoring '!$T$2=Table5[Machine]),Table5[Downtime]))} -> 0.0175 | W5: =U5-T5-V5 -> 0.3575 | X5: 9 | Y5: =X5/W5/24 -> 1.048951 | Z5: 0.33333333 | AA5: 0.70833333 | AB5: {=SUM(IF((Table3[[#This Row],[TanggaK Produksi]]=Table5[Date])*('Daily Performance Monitoring '!$Z$2=Table5[Machine]),Table5[Downtime]))} -> 0.0022222222 | AC5: =AA5-Z5-AB5 -> 0.37277778 | AD5: 9 | AE5: =AD5/AC5/24 -> 1.0059613 | AF5: 0.33333333 | AG5: 0.70833333 | AH5: {=SUM(IF((Table3[[#This Row],[TanggaK Produksi]]=Table5[Date])*('Daily Performance Monitoring '!$AF$2=Table5[Machine]),Table5[Downtime]))} -> 0 | AI5: =AG5-AF5-AH5 -> 0.375 | AJ5: 9 | AK5: =AJ5/AI5/24 -> 1 | AL5: 0.33333333 | AM5: 0.70833333 | AN5: {=SUM(IF((Table3[[#This Row],[TanggaK Produksi]]=Table5[Date])*('Daily Performance Monitoring '!$AL$2=Table5[Machine]),Table5[Downtime]))} -> 0 | AO5: =AM5-AL5-AN5 -> 0.375 | AP5: 12 | AQ5: =AP5/AO5/24 -> 1.3333333 | AR5: 0.33333333 | AS5: 0.70833333 | AT5: {=SUM(IF((Table3[[#This Row],[TanggaK Produksi]]=Table5[Date])*('Daily Performance Monitoring '!$AR$2=Table5[Machine]),Table5[Downtime]))} -> 0.063888889 | AU5: =AS5-AR5-AT5 -> 0.31111111 | AV5: 10 | AW5: =AV5/AU5/24 -> 1.3392857 | AX5: 0.33333333 | AY5: 0.70833333 | AZ5: {=SUM(IF((Table3[[#This Row],[TanggaK Produksi]]=Table5[Date])*('Daily Performance Monitoring '!$AX$2=Table5[Machine]),Table5[Downtime]))} -> 0 | BA5: =AY5-AX5-AZ5 -> 0.375 | BB5: 12 | BC5: =BB5/BA5/24 -> 1.3333333 | BE5: BRDR2 | BF5: =K20 -> 0.099175926 | BG5: =AVERAGE(K4:K19) -> 0.37190972 | BH5: =L20 -> 166 | BI5: =M20 -> 1.1623565
A6: 45903 | B6: 0.33333333 | C6: 0.70833333 | D6: {=SUM(IF((Table3[[#This Row],[TanggaK Produksi]]=Table5[Date])*('Daily Performance Monitoring '!$B$2=Table5[Machine]),Table5[Downtime]))} -> 0 | E6: =C6-B6-D6 -> 0.375 | F6: 11 | G6: =F6/E6/24 -> 1.2222222 | H6: 0.33333333 | I6: 0.70833333 | J6: {=SUM(IF((Table3[[#This Row],[TanggaK Produksi]]=Table5[Date])*('Daily Performance Monitoring '!$H$2=Table5[Machine]),Table5[Downtime]))} -> 0 | K6: =I6-H6-J6 -> 0.375 | L6: 9 | M6: =L6/K6/24 -> 1 | N6: 0.33333333 | O6: 0.70833333 | P6: {=SUM(IF((Table3[[#This Row],[TanggaK Produksi]]=Table5[Date])*('Daily Performance Monitoring '!$N$2=Table5[Machine]),Table5[Downtime]))} -> 0 | Q6: =O6-N6-P6 -> 0.375 | R6: 9 | S6: =R6/Q6/24 -> 1 | T6: 0.33333333 | U6: 0.70833333 | V6: {=SUM(IF((Table3[[#This Row],[TanggaK Produksi]]=Table5[Date])*('Daily Performance Monitoring '!$T$2=Table5[Machine]),Table5[Downtime]))} -> 0 | W6: =U6-T6-V6 -> 0.375 | X6: 10 | Y6: =X6/W6/24 -> 1.1111111 | Z6: 0.33333333 | AA6: 0.70833333 | AB6: {=SUM(IF((Table3[[#This Row],[TanggaK Produksi]]=Table5[Date])*('Daily Performance Monitoring '!$Z$2=Table5[Machine]),Table5[Downtime]))} -> 0 | AC6: =AA6-Z6-AB6 -> 0.375 | AD6: 10 | AE6: =AD6/AC6/24 -> 1.1111111 | AF6: 0.33333333 | AG6: 0.70833333 | AH6: {=SUM(IF((Table3[[#This Row],[TanggaK Produksi]]=Table5[Date])*('Daily Performance Monitoring '!$AF$2=Table5[Machine]),Table5[Downtime]))} -> 0 | AI6: =AG6-AF6-AH6 -> 0.375 | AJ6: 11 | AK6: =AJ6/AI6/24 -> 1.2222222 | AL6: 0.33333333 | AM6: 0.70833333 | AN6: {=SUM(IF((Table3[[#This Row],[TanggaK Produksi]]=Table5[Date])*('Daily Performance Monitoring '!$AL$2=Table5[Machine]),Table5[Downtime]))} -> 0 | AO6: =AM6-AL6-AN6 -> 0.375 | AP6: 11 | AQ6: =AP6/AO6/24 -> 1.2222222 | AR6: 0.33333333 | AS6: 0.70833333 | AT6: {=SUM(IF((Table3[[#This Row],[TanggaK Produksi]]=Table5[Date])*('Daily Performance Monitoring '!$AR$2=Table5[Machine]),Table5[Downtime]))} -> 0.048888889 | AU6: =AS6-AR6-AT6 -> 0.32611111 | AV6: 11 | AW6: =AV6/AU6/24 -> 1.4054514 | AX6: 0.33333333 | AY6: 0.70833333 | AZ6: {=SUM(IF((Table3[[#This Row],[TanggaK Produksi]]=Table5[Date])*('Daily Performance Monitoring '!$AX$2=Table5[Machine]),Table5[Downtime]))} -> 0.045555556 | BA6: =AY6-AX6-AZ6 -> 0.32944444 | BB6: 10 | BC6: =BB6/BA6/24 -> 1.2647555 | BE6: BRDR3 | BF6: =Q20 -> 0.099652778 | BG6: =AVERAGE(Q4:Q19) -> 0.37369792 | BH6: =R20 -> 168 | BI6: =S20 -> 1.1707317
A7: 45904 | B7: 0.33333333 | C7: 0.70833333 | D7: {=SUM(IF((Table3[[#This Row],[TanggaK Produksi]]=Table5[Date])*('Daily Performance Monitoring '!$B$2=Table5[Machine]),Table5[Downtime]))} -> 0 | E7: =C7-B7-D7 -> 0.375 | F7: 11 | G7: =F7/E7/24 -> 1.2222222 | H7: 0.33333333 | I7: 0.70833333 | J7: {=SUM(IF((Table3[[#This Row],[TanggaK Produksi]]=Table5[Date])*('Daily Performance Monitoring '!$H$2=Table5[Machine]),Table5[Downtime]))} -> 0 | K7: =I7-H7-J7 -> 0.375 | L7: 10 | M7: =L7/K7/24 -> 1.1111111 | N7: 0.33333333 | O7: 0.70833333 | P7: {=SUM(IF((Table3[[#This Row],[TanggaK Produksi]]=Table5[Date])*('Daily Performance Monitoring '!$N$2=Table5[Machine]),Table5[Downtime]))} -> 0 | Q7: =O7-N7-P7 -> 0.375 | R7: 12 | S7: =R7/Q7/24 -> 1.3333333 | T7: 0.33333333 | U7: 0.70833333 | V7: {=SUM(IF((Table3[[#This Row],[TanggaK Produksi]]=Table5[Date])*('Daily Performance Monitoring '!$T$2=Table5[Machine]),Table5[Downtime]))} -> 0 | W7: =U7-T7-V7 -> 0.375 | X7: 9 | Y7: =X7/W7/24 -> 1 | Z7: 0.33333333 | AA7: 0.70833333 | AB7: {=SUM(IF((Table3[[#This Row],[TanggaK Produksi]]=Table5[Date])*('Daily Performance Monitoring '!$Z$2=Table5[Machine]),Table5[Downtime]))} -> 0 | AC7: =AA7-Z7-AB7 -> 0.375 | AD7: 11 | AE7: =AD7/AC7/24 -> 1.2222222 | AF7: 0.33333333 | AG7: 0.70833333 | AH7: {=SUM(IF((Table3[[#This Row],[TanggaK Produksi]]=Table5[Date])*('Daily Performance Monitoring '!$AF$2=Table5[Machine]),Table5[Downtime]))} -> 0 | AI7: =AG7-AF7-AH7 -> 0.375 | AJ7: 9 | AK7: =AJ7/AI7/24 -> 1 | AL7: 0.33333333 | AM7: 0.70833333 | AN7: {=SUM(IF((Table3[[#This Row],[TanggaK Produksi]]=Table5[Date])*('Daily Performance Monitoring '!$AL$2=Table5[Machine]),Table5[Downtime]))} -> 0 | AO7: =AM7-AL7-AN7 -> 0.375 | AP7: 10 | AQ7: =AP7/AO7/24 -> 1.1111111 | AR7: 0.33333333 | AS7: 0.70833333 | AT7: {=SUM(IF((Table3[[#This Row],[TanggaK Produksi]]=Table5[Date])*('Daily Performance Monitoring '!$AR$2=Table5[Machine]),Table5[Downtime]))} -> 0.031944444 | AU7: =AS7-AR7-AT7 -> 0.34305556 | AV7: 12 | AW7: =AV7/AU7/24 -> 1.4574899 | AX7: 0.33333333 | AY7: 0.70833333 | AZ7: {=SUM(IF((Table3[[#This Row],[TanggaK Produksi]]=Table5[Date])*('Daily Performance Monitoring '!$AX$2=Table5[Machine]),Table5[Downtime]))} -> 0 | BA7: =AY7-AX7-AZ7 -> 0.375 | BB7: 10 | BC7: =BB7/BA7/24 -> 1.1111111 | BE7: BRDR4 | BF7: =W20 -> 0.099143519 | BG7: =AVERAGE(W4:W19) -> 0.37178819 | BH7: =X20 -> 164 | BI7: =Y20 -> 1.1487275
A8: 45905 | B8: 0.33333333 | C8: 0.70833333 | D8: {=SUM(IF((Table3[[#This Row],[TanggaK Produksi]]=Table5[Date])*('Daily Performance Monitoring '!$B$2=Table5[Machine]),Table5[Downtime]))} -> 0 | E8: =C8-B8-D8 -> 0.375 | F8: 12 | G8: =F8/E8/24 -> 1.3333333 | H8: 0.33333333 | I8: 0.70833333 | J8: {=SUM(IF((Table3[[#This Row],[TanggaK Produksi]]=Table5[Date])*('Daily Performance Monitoring '!$H$2=Table5[Machine]),Table5[Downtime]))} -> 0 | K8: =I8-H8-J8 -> 0.375 | L8: 11 | M8: =L8/K8/24 -> 1.2222222 | N8: 0.33333333 | O8: 0.70833333 | P8: {=SUM(IF((Table3[[#This Row],[TanggaK Produksi]]=Table5[Date])*('Daily Performance Monitoring '!$N$2=Table5[Machine]),Table5[Downtime]))} -> 0 | Q8: =O8-N8-P8 -> 0.375 | R8: 12 | S8: =R8/Q8/24 -> 1.3333333 | T8: 0.33333333 | U8: 0.70833333 | V8: {=SUM(IF((Table3[[#This Row],[TanggaK Produksi]]=Table5[Date])*('Daily Performance Monitoring '!$T$2=Table5[Machine]),Table5[Downtime]))} -> 0 | W8: =U8-T8-V8 -> 0.375 | X8: 11 | Y8: =X8/W8/24 -> 1.2222222 | Z8: 0.33333333 | AA8: 0.70833333 | AB8: {=SUM(IF((Table3[[#This Row],[TanggaK Produksi]]=Table5[Date])*('Daily Performance Monitoring '!$Z$2=Table5[Machine]),Table5[Downtime]))} -> 0.039722222 | AC8: =AA8-Z8-AB8 -> 0.33527778 | AD8: 11 | AE8: =AD8/AC8/24 -> 1.3670257 | AF8: 0.33333333 | AG8: 0.70833333 | AH8: {=SUM(IF((Table3[[#This Row],[TanggaK Produksi]]=Table5[Date])*('Daily Performance Monitoring '!$AF$2=Table5[Machine]),Table5[Downtime]))} -> 0 | AI8: =AG8-AF8-AH8 -> 0.375 | AJ8: 12 | AK8: =AJ8/AI8/24 -> 1.3333333 | AL8: 0.33333333 | AM8: 0.70833333 | AN8: {=SUM(IF((Table3[[#This Row],[TanggaK Produksi]]=Table5[Date])*('Daily Performance Monitoring '!$AL$2=Table5[Machine]),Table5[Downtime]))} -> 0 | AO8: =AM8-AL8-AN8 -> 0.375 | AP8: 11 | AQ8: =AP8/AO8/24 -> 1.2222222 | AR8: 0.33333333 | AS8: 0.70833333 | AT8: {=SUM(IF((Table3[[#This Row],[TanggaK Produksi]]=Table5[Date])*('Daily Performance Monitoring '!$AR$2=Table5[Machine]),Table5[Downtime]))} -> 0 | AU8: =AS8-AR8-AT8 -> 0.375 | AV8: 10 | AW8: =AV8/AU8/24 -> 1.1111111 | AX8: 0.33333333 | AY8: 0.70833333 | AZ8: {=SUM(IF((Table3[[#This Row],[TanggaK Produksi]]=Table5[Date])*('Daily Performance Monitoring '!$AX$2=Table5[Machine]),Table5[Downtime]))} -> 0.041111111 | BA8: =AY8-AX8-AZ8 -> 0.33388889 | BB8: 10 | BC8: =BB8/BA8/24 -> 1.2479201 | BE8: BRDR5 | BF8: =AC20 -> 0.098643519 | BG8: =AVERAGE(AC4:AC19) -> 0.36991319 | BH8: =AD20 -> 170 | BI8: =AE20 -> 1.1967898
A9: 45906 | B9: 0.33333333 | C9: 0.70833333 | D9: {=SUM(IF((Table3[[#This Row],[TanggaK Produksi]]=Table5[Date])*('Daily Performance Monitoring '!$B$2=Table5[Machine]),Table5[Downtime]))} -> 0 | E9: =C9-B9-D9 -> 0.375 | F9: 9 | G9: =F9/E9/24 -> 1 | H9: 0.33333333 | I9: 0.70833333 | J9: {=SUM(IF((Table3[[#This Row],[TanggaK Produksi]]=Table5[Date])*('Daily Performance Monitoring '!$H$2=Table5[Machine]),Table5[Downtime]))} -> 0 | K9: =I9-H9-J9 -> 0.375 | L9: 11 | M9: =L9/K9/24 -> 1.2222222 | N9: 0.33333333 | O9: 0.70833333 | P9: {=SUM(IF((Table3[[#This Row],[TanggaK Produksi]]=Table5[Date])*('Daily Performance Monitoring '!$N$2=Table5[Machine]),Table5[Downtime]))} -> 0 | Q9: =O9-N9-P9 -> 0.375 | R9: 11 | S9: =R9/Q9/24 -> 1.2222222 | T9: 0.33333333 | U9: 0.70833333 | V9: {=SUM(IF((Table3[[#This Row],[TanggaK Produksi]]=Table5[Date])*('Daily Performance Monitoring '!$T$2=Table5[Machine]),Table5[Downtime]))} -> 0.01 | W9: =U9-T9-V9 -> 0.365 | X9: 9 | Y9: =X9/W9/24 -> 1.0273973 | Z9: 0.33333333 | AA9: 0.70833333 | AB9: {=SUM(IF((Table3[[#This Row],[TanggaK Produksi]]=Table5[Date])*('Daily Performance Monitoring '!$Z$2=Table5[Machine]),Table5[Downtime]))} -> 0 | AC9: =AA9-Z9-AB9 -> 0.375 | AD9: 12 | AE9: =AD9/AC9/24 -> 1.3333333 | AF9: 0.33333333 | AG9: 0.70833333 | AH9: {=SUM(IF((Table3[[#This Row],[TanggaK Produksi]]=Table5[Date])*('Daily Performance Monitoring '!$AF$2=Table5[Machine]),Table5[Downtime]))} -> 0 | AI9: =AG9-AF9-AH9 -> 0.375 | AJ9: 9 | AK9: =AJ9/AI9/24 -> 1 | AL9: 0.33333333 | AM9: 0.70833333 | AN9: {=SUM(IF((Table3[[#This Row],[TanggaK Produksi]]=Table5[Date])*('Daily Performance Monitoring '!$AL$2=Table5[Machine]),Table5[Downtime]))} -> 0.031666667 | AO9: =AM9-AL9-AN9 -> 0.34333333 | AP9: 10 | AQ9: =AP9/AO9/24 -> 1.2135922 | AR9: 0.33333333 | AS9: 0.70833333 | AT9: {=SUM(IF((Table3[[#This Row],[TanggaK Produksi]]=Table5[Date])*('Daily Performance Monitoring '!$AR$2=Table5[Machine]),Table5[Downtime]))} -> 0 | AU9: =AS9-AR9-AT9 -> 0.375 | AV9: 9 | AW9: =AV9/AU9/24 -> 1 | AX9: 0.33333333 | AY9: 0.70833333 | AZ9: {=SUM(IF((Table3[[#This Row],[TanggaK Produksi]]=Table5[Date])*('Daily Performance Monitoring '!$AX$2=Table5[Machine]),Table5[Downtime]))} -> 0 | BA9: =AY9-AX9-AZ9 -> 0.375 | BB9: 9 | BC9: =BB9/BA9/24 -> 1 | BE9: BRDR6 | BF9: =AI20 -> 0.098861111 | BG9: =AVERAGE(AI4:AI19) -> 0.37072917 | BH9: =AJ20 -> 170 | BI9: =AK20 -> 1.1941557
A10: 45908 | B10: 0.33333333 | C10: 0.70833333 | D10: {=SUM(IF((Table3[[#This Row],[TanggaK Produksi]]=Table5[Date])*('Daily Performance Monitoring '!$B$2=Table5[Machine]),Table5[Downtime]))} -> 0 | E10: =C10-B10-D10 -> 0.375 | F10: 11 | G10: =F10/E10/24 -> 1.2222222 | H10: 0.33333333 | I10: 0.70833333 | J10: {=SUM(IF((Table3[[#This Row],[TanggaK Produksi]]=Table5[Date])*('Daily Performance Monitoring '!$H$2=Table5[Machine]),Table5[Downtime]))} -> 0 | K10: =I10-H10-J10 -> 0.375 | L10: 10 | M10: =L10/K10/24 -> 1.1111111 | N10: 0.33333333 | O10: 0.70833333 | P10: {=SUM(IF((Table3[[#This Row],[TanggaK Produksi]]=Table5[Date])*('Daily Performance Monitoring '!$N$2=Table5[Machine]),Table5[Downtime]))} -> 0.0175 | Q10: =O10-N10-P10 -> 0.3575 | R10: 12 | S10: =R10/Q10/24 -> 1.3986014 | T10: 0.33333333 | U10: 0.70833333 | V10: {=SUM(IF((Table3[[#This Row],[TanggaK Produksi]]=Table5[Date])*('Daily Performance Monitoring '!$T$2=Table5[Machine]),Table5[Downtime]))} -> 0 | W10: =U10-T10-V10 -> 0.375 | X10: 10 | Y10: =X10/W10/24 -> 1.1111111 | Z10: 0.33333333 | AA10: 0.70833333 | AB10: {=SUM(IF((Table3[[#This Row],[TanggaK Produksi]]=Table5[Date])*('Daily Performance Monitoring '!$Z$2=Table5[Machine]),Table5[Downtime]))} -> 0 | AC10: =AA10-Z10-AB10 -> 0.375 | AD10: 12 | AE10: =AD10/AC10/24 -> 1.3333333 | AF10: 0.33333333 | AG10: 0.70833333 | AH10: {=SUM(IF((Table3[[#This Row],[TanggaK Produksi]]=Table5[Date])*('Daily Performance Monitoring '!$AF$2=Table5[Machine]),Table5[Downtime]))} -> 0 | AI10: =AG10-AF10-AH10 -> 0.375 | AJ10: 9 | AK10: =AJ10/AI10/24 -> 1 | AL10: 0.33333333 | AM10: 0.70833333 | AN10: {=SUM(IF((Table3[[#This Row],[TanggaK Produksi]]=Table5[Date])*('Daily Performance Monitoring '!$AL$2=Table5[Machine]),Table5[Downtime]))} -> 0 | AO10: =AM10-AL10-AN10 -> 0.375 | AP10: 12 | AQ10: =AP10/AO10/24 -> 1.3333333 | AR10: 0.33333333 | AS10: 0.70833333 | AT10: {=SUM(IF((Table3[[#This Row],[TanggaK Produksi]]=Table5[Date])*('Daily Performance Monitoring '!$AR$2=Table5[Machine]),Table5[Downtime]))} -> 0 | AU10: =AS10-AR10-AT10 -> 0.375 | AV10: 12 | AW10: =AV10/AU10/24 -> 1.3333333 | AX10: 0.33333333 | AY10: 0.70833333 | AZ10: {=SUM(IF((Table3[[#This Row],[TanggaK Produksi]]=Table5[Date])*('Daily Performance Monitoring '!$AX$2=Table5[Machine]),Table5[Downtime]))} -> 0 | BA10: =AY10-AX10-AZ10 -> 0.375 | BB10: 10 | BC10: =BB10/BA10/24 -> 1.1111111 | BE10: BRDR7 | BF10: =AO20 -> 0.098583333 | BG10: =AVERAGE(AO4:AO19) -> 0.3696875 | BH10: =AP20 -> 171 | BI10: =AQ20 -> 1.2045647
A11: 45909 | B11: 0.33333333 | C11: 0.70833333 | D11: {=SUM(IF((Table3[[#This Row],[TanggaK Produksi]]=Table5[Date])*('Daily Performance Monitoring '!$B$2=Table5[Machine]),Table5[Downtime]))} -> 0 | E11: =C11-B11-D11 -> 0.375 | F11: 10 | G11: =F11/E11/24 -> 1.1111111 | H11: 0.33333333 | I11: 0.70833333 | J11: {=SUM(IF((Table3[[#This Row],[TanggaK Produksi]]=Table5[Date])*('Daily Performance Monitoring '!$H$2=Table5[Machine]),Table5[Downtime]))} -> 0 | K11: =I11-H11-J11 -> 0.375 | L11: 10 | M11: =L11/K11/24 -> 1.1111111 | N11: 0.33333333 | O11: 0.70833333 | P11: {=SUM(IF((Table3[[#This Row],[TanggaK Produksi]]=Table5[Date])*('Daily Performance Monitoring '!$N$2=Table5[Machine]),Table5[Downtime]))} -> 0 | Q11: =O11-N11-P11 -> 0.375 | R11: 9 | S11: =R11/Q11/24 -> 1 | T11: 0.33333333 | U11: 0.70833333 | V11: {=SUM(IF((Table3[[#This Row],[TanggaK Produksi]]=Table5[Date])*('Daily Performance Monitoring '!$T$2=Table5[Machine]),Table5[Downtime]))} -> 0 | W11: =U11-T11-V11 -> 0.375 | X11: 11 | Y11: =X11/W11/24 -> 1.2222222 | Z11: 0.33333333 | AA11: 0.70833333 | AB11: {=SUM(IF((Table3[[#This Row],[TanggaK Produksi]]=Table5[Date])*('Daily Performance Monitoring '!$Z$2=Table5[Machine]),Table5[Downtime]))} -> 0.034166667 | AC11: =AA11-Z11-AB11 -> 0.34083333 | AD11: 11 | AE11: =AD11/AC11/24 -> 1.3447433 | AF11: 0.33333333 | AG11: 0.70833333 | AH11: {=SUM(IF((Table3[[#This Row],[TanggaK Produksi]]=Table5[Date])*('Daily Performance Monitoring '!$AF$2=Table5[Machine]),Table5[Downtime]))} -> 0.012777778 | AI11: =AG11-AF11-AH11 -> 0.36222222 | AJ11: 12 | AK11: =AJ11/AI11/24 -> 1.3803681 | AL11: 0.33333333 | AM11: 0.70833333 | AN11: {=SUM(IF((Table3[[#This Row],[TanggaK Produksi]]=Table5[Date])*('Daily Performance Monitoring '!$AL$2=Table5[Machine]),Table5[Downtime]))} -> 0.022222222 | AO11: =AM11-AL11-AN11 -> 0.35277778 | AP11: 11 | AQ11: =AP11/AO11/24 -> 1.2992126 | AR11: 0.33333333 | AS11: 0.70833333 | AT11: {=SUM(IF((Table3[[#This Row],[TanggaK Produksi]]=Table5[Date])*('Daily Performance Monitoring '!$AR$2=Table5[Machine]),Table5[Downtime]))} -> 0 | AU11: =AS11-AR11-AT11 -> 0.375 | AV11: 10 | AW11: =AV11/AU11/24 -> 1.1111111 | AX11: 0.33333333 | AY11: 0.70833333 | AZ11: {=SUM(IF((Table3[[#This Row],[TanggaK Produksi]]=Table5[Date])*('Daily Performance Monitoring '!$AX$2=Table5[Machine]),Table5[Downtime]))} -> 0.020833333 | BA11: =AY11-AX11-AZ11 -> 0.35416667 | BB11: 9 | BC11: =BB11/BA11/24 -> 1.0588235 | BE11: BRDR8 | BF11: =AU20 -> 0.097143519 | BG11: =AVERAGE(AU4:AU19) -> 0.36428819 | BH11: =AV20 -> 173 | BI11: =AW20 -> 1.2367154
A12: 45910 | B12: 0.33333333 | C12: 0.70833333 | D12: {=SUM(IF((Table3[[#This Row],[TanggaK Produksi]]=Table5[Date])*('Daily Performance Monitoring '!$B$2=Table5[Machine]),Table5[Downtime]))} -> 0 | E12: =C12-B12-D12 -> 0.375 | F12: 12 | G12: =F12/E12/24 -> 1.3333333 | H12: 0.33333333 | I12: 0.70833333 | J12: {=SUM(IF((Table3[[#This Row],[TanggaK Produksi]]=Table5[Date])*('Daily Performance Monitoring '!$H$2=Table5[Machine]),Table5[Downtime]))} -> 0 | K12: =I12-H12-J12 -> 0.375 | L12: 10 | M12: =L12/K12/24 -> 1.1111111 | N12: 0.33333333 | O12: 0.70833333 | P12: {=SUM(IF((Table3[[#This Row],[TanggaK Produksi]]=Table5[Date])*('Daily Performance Monitoring '!$N$2=Table5[Machine]),Table5[Downtime]))} -> 0 | Q12: =O12-N12-P12 -> 0.375 | R12: 12 | S12: =R12/Q12/24 -> 1.3333333 | T12: 0.33333333 | U12: 0.70833333 | V12: {=SUM(IF((Table3[[#This Row],[TanggaK Produksi]]=Table5[Date])*('Daily Performance Monitoring '!$T$2=Table5[Machine]),Table5[Downtime]))} -> 0 | W12: =U12-T12-V12 -> 0.375 | X12: 9 | Y12: =X12/W12/24 -> 1 | Z12: 0.33333333 | AA12: 0.70833333 | AB12: {=SUM(IF((Table3[[#This Row],[TanggaK Produksi]]=Table5[Date])*('Daily Performance Monitoring '!$Z$2=Table5[Machine]),Table5[Downtime]))} -> 0 | AC12: =AA12-Z12-AB12 -> 0.375 | AD12: 12 | AE12: =AD12/AC12/24 -> 1.3333333 | AF12: 0.33333333 | AG12: 0.70833333 | AH12: {=SUM(IF((Table3[[#This Row],[TanggaK Produksi]]=Table5[Date])*('Daily Performance Monitoring '!$AF$2=Table5[Machine]),Table5[Downtime]))} -> 0 | AI12: =AG12-AF12-AH12 -> 0.375 | AJ12: 12 | AK12: =AJ12/AI12/24 -> 1.3333333 | AL12: 0.33333333 | AM12: 0.70833333 | AN12: {=SUM(IF((Table3[[#This Row],[TanggaK Produksi]]=Table5[Date])*('Daily Performance Monitoring '!$AL$2=Table5[Machine]),Table5[Downtime]))} -> 0.031111111 | AO12: =AM12-AL12-AN12 -> 0.34388889 | AP12: 9 | AQ12: =AP12/AO12/24 -> 1.0904685 | AR12: 0.33333333 | AS12: 0.70833333 | AT12: {=SUM(IF((Table3[[#This Row],[TanggaK Produksi]]=Table5[Date])*('Daily Performance Monitoring '!$AR$2=Table5[Machine]),Table5[Downtime]))} -> 0 | AU12: =AS12-AR12-AT12 -> 0.375 | AV12: 10 | AW12: =AV12/AU12/24 -> 1.1111111 | AX12: 0.33333333 | AY12: 0.70833333 | AZ12: {=SUM(IF((Table3[[#This Row],[TanggaK Produksi]]=Table5[Date])*('Daily Performance Monitoring '!$AX$2=Table5[Machine]),Table5[Downtime]))} -> 0 | BA12: =AY12-AX12-AZ12 -> 0.375 | BB12: 12 | BC12: =BB12/BA12/24 -> 1.3333333 | BE12: BRDR9 | BF12: =BA20 -> 0.097328704 | BG12: =AVERAGE(BA4:BA19) -> 0.36498264 | BH12: =BB20 -> 166 | BI12: =BC20 -> 1.1844171
A13: 45911 | B13: 0.33333333 | C13: 0.70833333 | D13: {=SUM(IF((Table3[[#This Row],[TanggaK Produksi]]=Table5[Date])*('Daily Performance Monitoring '!$B$2=Table5[Machine]),Table5[Downtime]))} -> 0.019722222 | E13: =C13-B13-D13 -> 0.35527778 | F13: 12 | G13: =F13/E13/24 -> 1.4073495 | H13: 0.33333333 | I13: 0.70833333 | J13: {=SUM(IF((Table3[[#This Row],[TanggaK Produksi]]=Table5[Date])*('Daily Performance Monitoring '!$H$2=Table5[Machine]),Table5[Downtime]))} -> 0 | K13: =I13-H13-J13 -> 0.375 | L13: 9 | M13: =L13/K13/24 -> 1 | N13: 0.33333333 | O13: 0.70833333 | P13: {=SUM(IF((Table3[[#This Row],[TanggaK Produksi]]=Table5[Date])*('Daily Performance Monitoring '!$N$2=Table5[Machine]),Table5[Downtime]))} -> 0 | Q13: =O13-N13-P13 -> 0.375 | R13: 9 | S13: =R13/Q13/24 -> 1 | T13: 0.33333333 | U13: 0.70833333 | V13: {=SUM(IF((Table3[[#This Row],[TanggaK Produksi]]=Table5[Date])*('Daily Performance Monitoring '!$T$2=Table5[Machine]),Table5[Downtime]))} -> 0 | W13: =U13-T13-V13 -> 0.375 | X13: 10 | Y13: =X13/W13/24 -> 1.1111111 | Z13: 0.33333333 | AA13: 0.70833333 | AB13: {=SUM(IF((Table3[[#This Row],[TanggaK Produksi]]=Table5[Date])*('Daily Performance Monitoring '!$Z$2=Table5[Machine]),Table5[Downtime]))} -> 0 | AC13: =AA13-Z13-AB13 -> 0.375 | AD13: 11 | AE13: =AD13/AC13/24 -> 1.2222222 | AF13: 0.33333333 | AG13: 0.70833333 | AH13: {=SUM(IF((Table3[[#This Row],[TanggaK Produksi]]=Table5[Date])*('Daily Performance Monitoring '!$AF$2=Table5[Machine]),Table5[Downtime]))} -> 0 | AI13: =AG13-AF13-AH13 -> 0.375 | AJ13: 12 | AK13: =AJ13/AI13/24 -> 1.3333333 | AL13: 0.33333333 | AM13: 0.70833333 | AN13: {=SUM(IF((Table3[[#This Row],[TanggaK Produksi]]=Table5[Date])*('Daily Performance Monitoring '!$AL$2=Table5[Machine]),Table5[Downtime]))} -> 0 | AO13: =AM13-AL13-AN13 -> 0.375 | AP13: 12 | AQ13: =AP13/AO13/24 -> 1.3333333 | AR13: 0.33333333 | AS13: 0.70833333 | AT13: {=SUM(IF((Table3[[#This Row],[TanggaK Produksi]]=Table5[Date])*('Daily Performance Monitoring '!$AR$2=Table5[Machine]),Table5[Downtime]))} -> 0.0036111111 | AU13: =AS13-AR13-AT13 -> 0.37138889 | AV13: 10 | AW13: =AV13/AU13/24 -> 1.1219147 | AX13: 0.33333333 | AY13: 0.70833333 | AZ13: {=SUM(IF((Table3[[#This Row],[TanggaK Produksi]]=Table5[Date])*('Daily Performance Monitoring '!$AX$2=Table5[Machine]),Table5[Downtime]))} -> 0.0069444444 | BA13: =AY13-AX13-AZ13 -> 0.36805556 | BB13: 9 | BC13: =BB13/BA13/24 -> 1.0188679
A14: 45912 | B14: 0.33333333 | C14: 0.70833333 | D14: {=SUM(IF((Table3[[#This Row],[TanggaK Produksi]]=Table5[Date])*('Daily Performance Monitoring '!$B$2=Table5[Machine]),Table5[Downtime]))} -> 0 | E14: =C14-B14-D14 -> 0.375 | F14: 10 | G14: =F14/E14/24 -> 1.1111111 | H14: 0.33333333 | I14: 0.70833333 | J14: {=SUM(IF((Table3[[#This Row],[TanggaK Produksi]]=Table5[Date])*('Daily Performance Monitoring '!$H$2=Table5[Machine]),Table5[Downtime]))} -> 0 | K14: =I14-H14-J14 -> 0.375 | L14: 12 | M14: =L14/K14/24 -> 1.3333333 | N14: 0.33333333 | O14: 0.70833333 | P14: {=SUM(IF((Table3[[#This Row],[TanggaK Produksi]]=Table5[Date])*('Daily Performance Monitoring '!$N$2=Table5[Machine]),Table5[Downtime]))} -> 0 | Q14: =O14-N14-P14 -> 0.375 | R14: 10 | S14: =R14/Q14/24 -> 1.1111111 | T14: 0.33333333 | U14: 0.70833333 | V14: {=SUM(IF((Table3[[#This Row],[TanggaK Produksi]]=Table5[Date])*('Daily Performance Monitoring '!$T$2=Table5[Machine]),Table5[Downtime]))} -> 0 | W14: =U14-T14-V14 -> 0.375 | X14: 10 | Y14: =X14/W14/24 -> 1.1111111 | Z14: 0.33333333 | AA14: 0.70833333 | AB14: {=SUM(IF((Table3[[#This Row],[TanggaK Produksi]]=Table5[Date])*('Daily Performance Monitoring '!$Z$2=Table5[Machine]),Table5[Downtime]))} -> 0 | AC14: =AA14-Z14-AB14 -> 0.375 | AD14: 10 | AE14: =AD14/AC14/24 -> 1.1111111 | AF14: 0.33333333 | AG14: 0.70833333 | AH14: {=SUM(IF((Table3[[#This Row],[TanggaK Produksi]]=Table5[Date])*('Daily Performance Monitoring '!$AF$2=Table5[Machine]),Table5[Downtime]))} -> 0.036666667 | AI14: =AG14-AF14-AH14 -> 0.33833333 | AJ14: 12 | AK14: =AJ14/AI14/24 -> 1.4778325 | AL14: 0.33333333 | AM14: 0.70833333 | AN14: {=SUM(IF((Table3[[#This Row],[TanggaK Produksi]]=Table5[Date])*('Daily Performance Monitoring '!$AL$2=Table5[Machine]),Table5[Downtime]))} -> 0 | AO14: =AM14-AL14-AN14 -> 0.375 | AP14: 12 | AQ14: =AP14/AO14/24 -> 1.3333333 | AR14: 0.33333333 | AS14: 0.70833333 | AT14: {=SUM(IF((Table3[[#This Row],[TanggaK Produksi]]=Table5[Date])*('Daily Performance Monitoring '!$AR$2=Table5[Machine]),Table5[Downtime]))} -> 0 | AU14: =AS14-AR14-AT14 -> 0.375 | AV14: 11 | AW14: =AV14/AU14/24 -> 1.2222222 | AX14: 0.33333333 | AY14: 0.70833333 | AZ14: {=SUM(IF((Table3[[#This Row],[TanggaK Produksi]]=Table5[Date])*('Daily Performance Monitoring '!$AX$2=Table5[Machine]),Table5[Downtime]))} -> 0.0036111111 | BA14: =AY14-AX14-AZ14 -> 0.37138889 | BB14: 11 | BC14: =BB14/BA14/24 -> 1.2341062
A15: 45913 | B15: 0.33333333 | C15: 0.70833333 | D15: {=SUM(IF((Table3[[#This Row],[TanggaK Produksi]]=Table5[Date])*('Daily Performance Monitoring '!$B$2=Table5[Machine]),Table5[Downtime]))} -> 0.040833333 | E15: =C15-B15-D15 -> 0.33416667 | F15: 12 | G15: =F15/E15/24 -> 1.4962594 | H15: 0.33333333 | I15: 0.70833333 | J15: {=SUM(IF((Table3[[#This Row],[TanggaK Produksi]]=Table5[Date])*('Daily Performance Monitoring '!$H$2=Table5[Machine]),Table5[Downtime]))} -> 0 | K15: =I15-H15-J15 -> 0.375 | L15: 9 | M15: =L15/K15/24 -> 1 | N15: 0.33333333 | O15: 0.70833333 | P15: {=SUM(IF((Table3[[#This Row],[TanggaK Produksi]]=Table5[Date])*('Daily Performance Monitoring '!$N$2=Table5[Machine]),Table5[Downtime]))} -> 0 | Q15: =O15-N15-P15 -> 0.375 | R15: 9 | S15: =R15/Q15/24 -> 1 | T15: 0.33333333 | U15: 0.70833333 | V15: {=SUM(IF((Table3[[#This Row],[TanggaK Produksi]]=Table5[Date])*('Daily Performance Monitoring '!$T$2=Table5[Machine]),Table5[Downtime]))} -> 0 | W15: =U15-T15-V15 -> 0.375 | X15: 10 | Y15: =X15/W15/24 -> 1.1111111 | Z15: 0.33333333 | AA15: 0.70833333 | AB15: {=SUM(IF((Table3[[#This Row],[TanggaK Produksi]]=Table5[Date])*('Daily Performance Monitoring '!$Z$2=Table5[Machine]),Table5[Downtime]))} -> 0 | AC15: =AA15-Z15-AB15 -> 0.375 | AD15: 10 | AE15: =AD15/AC15/24 -> 1.1111111 | AF15: 0.33333333 | AG15: 0.70833333 | AH15: {=SUM(IF((Table3[[#This Row],[TanggaK Produksi]]=Table5[Date])*('Daily Performance Monitoring '!$AF$2=Table5[Machine]),Table5[Downtime]))} -> 0 | AI15: =AG15-AF15-AH15 -> 0.375 | AJ15: 9 | AK15: =AJ15/AI15/24 -> 1 | AL15: 0.33333333 | AM15: 0.70833333 | AN15: {=SUM(IF((Table3[[#This Row],[TanggaK Produksi]]=Table5[Date])*('Daily Performance Monitoring '!$AL$2=Table5[Machine]),Table5[Downtime]))} -> 0 | AO15: =AM15-AL15-AN15 -> 0.375 | AP15: 11 | AQ15: =AP15/AO15/24 -> 1.2222222 | AR15: 0.33333333 | AS15: 0.70833333 | AT15: {=SUM(IF((Table3[[#This Row],[TanggaK Produksi]]=Table5[Date])*('Daily Performance Monitoring '!$AR$2=Table5[Machine]),Table5[Downtime]))} -> 0.01 | AU15: =AS15-AR15-AT15 -> 0.365 | AV15: 12 | AW15: =AV15/AU15/24 -> 1.369863 | AX15: 0.33333333 | AY15: 0.70833333 | AZ15: {=SUM(IF((Table3[[#This Row],[TanggaK Produksi]]=Table5[Date])*('Daily Performance Monitoring '!$AX$2=Table5[Machine]),Table5[Downtime]))} -> 0.013888889 | BA15: =AY15-AX15-AZ15 -> 0.36111111 | BB15: 11 | BC15: =BB15/BA15/24 -> 1.2692308
A16: 45915 | B16: 0.33333333 | C16: 0.70833333 | D16: {=SUM(IF((Table3[[#This Row],[TanggaK Produksi]]=Table5[Date])*('Daily Performance Monitoring '!$B$2=Table5[Machine]),Table5[Downtime]))} -> 0 | E16: =C16-B16-D16 -> 0.375 | F16: 10 | G16: =F16/E16/24 -> 1.1111111 | H16: 0.33333333 | I16: 0.70833333 | J16: {=SUM(IF((Table3[[#This Row],[TanggaK Produksi]]=Table5[Date])*('Daily Performance Monitoring '!$H$2=Table5[Machine]),Table5[Downtime]))} -> 0 | K16: =I16-H16-J16 -> 0.375 | L16: 11 | M16: =L16/K16/24 -> 1.2222222 | N16: 0.33333333 | O16: 0.70833333 | P16: {=SUM(IF((Table3[[#This Row],[TanggaK Produksi]]=Table5[Date])*('Daily Performance Monitoring '!$N$2=Table5[Machine]),Table5[Downtime]))} -> 0 | Q16: =O16-N16-P16 -> 0.375 | R16: 10 | S16: =R16/Q16/24 -> 1.1111111 | T16: 0.33333333 | U16: 0.70833333 | V16: {=SUM(IF((Table3[[#This Row],[TanggaK Produksi]]=Table5[Date])*('Daily Performance Monitoring '!$T$2=Table5[Machine]),Table5[Downtime]))} -> 0 | W16: =U16-T16-V16 -> 0.375 | X16: 12 | Y16: =X16/W16/24 -> 1.3333333 | Z16: 0.33333333 | AA16: 0.70833333 | AB16: {=SUM(IF((Table3[[#This Row],[TanggaK Produksi]]=Table5[Date])*('Daily Performance Monitoring '!$Z$2=Table5[Machine]),Table5[Downtime]))} -> 0.0052777778 | AC16: =AA16-Z16-AB16 -> 0.36972222 | AD16: 9 | AE16: =AD16/AC16/24 -> 1.014275 | AF16: 0.33333333 | AG16: 0.70833333 | AH16: {=SUM(IF((Table3[[#This Row],[TanggaK Produksi]]=Table5[Date])*('Daily Performance Monitoring '!$AF$2=Table5[Machine]),Table5[Downtime]))} -> 0 | AI16: =AG16-AF16-AH16 -> 0.375 | AJ16: 10 | AK16: =AJ16/AI16/24 -> 1.1111111 | AL16: 0.33333333 | AM16: 0.70833333 | AN16: {=SUM(IF((Table3[[#This Row],[TanggaK Produksi]]=Table5[Date])*('Daily Performance Monitoring '!$AL$2=Table5[Machine]),Table5[Downtime]))} -> 0 | AO16: =AM16-AL16-AN16 -> 0.375 | AP16: 11 | AQ16: =AP16/AO16/24 -> 1.2222222 | AR16: 0.33333333 | AS16: 0.70833333 | AT16: {=SUM(IF((Table3[[#This Row],[TanggaK Produksi]]=Table5[Date])*('Daily Performance Monitoring '!$AR$2=Table5[Machine]),Table5[Downtime]))} -> 0 | AU16: =AS16-AR16-AT16 -> 0.375 | AV16: 9 | AW16: =AV16/AU16/24 -> 1 | AX16: 0.33333333 | AY16: 0.70833333 | AZ16: {=SUM(IF((Table3[[#This Row],[TanggaK Produksi]]=Table5[Date])*('Daily Performance Monitoring '!$AX$2=Table5[Machine]),Table5[Downtime]))} -> 0 | BA16: =AY16-AX16-AZ16 -> 0.375 | BB16: 10 | BC16: =BB16/BA16/24 -> 1.1111111
A17: 45916 | B17: 0.33333333 | C17: 0.70833333 | D17: {=SUM(IF((Table3[[#This Row],[TanggaK Produksi]]=Table5[Date])*('Daily Performance Monitoring '!$B$2=Table5[Machine]),Table5[Downtime]))} -> 0.0080555556 | E17: =C17-B17-D17 -> 0.36694444 | F17: 10 | G17: =F17/E17/24 -> 1.1355034 | H17: 0.33333333 | I17: 0.70833333 | J17: {=SUM(IF((Table3[[#This Row],[TanggaK Produksi]]=Table5[Date])*('Daily Performance Monitoring '!$H$2=Table5[Machine]),Table5[Downtime]))} -> 0 | K17: =I17-H17-J17 -> 0.375 | L17: 12 | M17: =L17/K17/24 -> 1.3333333 | N17: 0.33333333 | O17: 0.70833333 | P17: {=SUM(IF((Table3[[#This Row],[TanggaK Produksi]]=Table5[Date])*('Daily Performance Monitoring '!$N$2=Table5[Machine]),Table5[Downtime]))} -> 0 | Q17: =O17-N17-P17 -> 0.375 | R17: 11 | S17: =R17/Q17/24 -> 1.2222222 | T17: 0.33333333 | U17: 0.70833333 | V17: {=SUM(IF((Table3[[#This Row],[TanggaK Produksi]]=Table5[Date])*('Daily Performance Monitoring '!$T$2=Table5[Machine]),Table5[Downtime]))} -> 0 | W17: =U17-T17-V17 -> 0.375 | X17: 12 | Y17: =X17/W17/24 -> 1.3333333 | Z17: 0.33333333 | AA17: 0.70833333 | AB17: {=SUM(IF((Table3[[#This Row],[TanggaK Produksi]]=Table5[Date])*('Daily Performance Monitoring '!$Z$2=Table5[Machine]),Table5[Downtime]))} -> 0 | AC17: =AA17-Z17-AB17 -> 0.375 | AD17: 10 | AE17: =AD17/AC17/24 -> 1.1111111 | AF17: 0.33333333 | AG17: 0.70833333 | AH17: {=SUM(IF((Table3[[#This Row],[TanggaK Produksi]]=Table5[Date])*('Daily Performance Monitoring '!$AF$2=Table5[Machine]),Table5[Downtime]))} -> 0.018888889 | AI17: =AG17-AF17-AH17 -> 0.35611111 | AJ17: 10 | AK17: =AJ17/AI17/24 -> 1.1700468 | AL17: 0.33333333 | AM17: 0.70833333 | AN17: {=SUM(IF((Table3[[#This Row],[TanggaK Produksi]]=Table5[Date])*('Daily Performance Monitoring '!$AL$2=Table5[Machine]),Table5[Downtime]))} -> 0 | AO17: =AM17-AL17-AN17 -> 0.375 | AP17: 9 | AQ17: =AP17/AO17/24 -> 1 | AR17: 0.33333333 | AS17: 0.70833333 | AT17: {=SUM(IF((Table3[[#This Row],[TanggaK Produksi]]=Table5[Date])*('Daily Performance Monitoring '!$AR$2=Table5[Machine]),Table5[Downtime]))} -> 0 | AU17: =AS17-AR17-AT17 -> 0.375 | AV17: 12 | AW17: =AV17/AU17/24 -> 1.3333333 | AX17: 0.33333333 | AY17: 0.70833333 | AZ17: {=SUM(IF((Table3[[#This Row],[TanggaK Produksi]]=Table5[Date])*('Daily Performance Monitoring '!$AX$2=Table5[Machine]),Table5[Downtime]))} -> 0 | BA17: =AY17-AX17-AZ17 -> 0.375 | BB17: 9 | BC17: =BB17/BA17/24 -> 1
A18: 45917 | B18: 0.33333333 | C18: 0.70833333 | D18: {=SUM(IF((Table3[[#This Row],[TanggaK Produksi]]=Table5[Date])*('Daily Performance Monitoring '!$B$2=Table5[Machine]),Table5[Downtime]))} -> 0 | E18: =C18-B18-D18 -> 0.375 | F18: 10 | G18: =F18/E18/24 -> 1.1111111 | H18: 0.33333333 | I18: 0.70833333 | J18: {=SUM(IF((Table3[[#This Row],[TanggaK Produksi]]=Table5[Date])*('Daily Performance Monitoring '!$H$2=Table5[Machine]),Table5[Downtime]))} -> 0.035555556 | K18: =I18-H18-J18 -> 0.33944444 | L18: 10 | M18: =L18/K18/24 -> 1.2274959 | N18: 0.33333333 | O18: 0.70833333 | P18: {=SUM(IF((Table3[[#This Row],[TanggaK Produksi]]=Table5[Date])*('Daily Performance Monitoring '!$N$2=Table5[Machine]),Table5[Downtime]))} -> 0 | Q18: =O18-N18-P18 -> 0.375 | R18: 12 | S18: =R18/Q18/24 -> 1.3333333 | T18: 0.33333333 | U18: 0.70833333 | V18: {=SUM(IF((Table3[[#This Row],[TanggaK Produksi]]=Table5[Date])*('Daily Performance Monitoring '!$T$2=Table5[Machine]),Table5[Downtime]))} -> 0.023888889 | W18: =U18-T18-V18 -> 0.35111111 | X18: 9 | Y18: =X18/W18/24 -> 1.068038 | Z18: 0.33333333 | AA18: 0.70833333 | AB18: {=SUM(IF((Table3[[#This Row],[TanggaK Produksi]]=Table5[Date])*('Daily Performance Monitoring '!$Z$2=Table5[Machine]),Table5[Downtime]))} -> 0 | AC18: =AA18-Z18-AB18 -> 0.375 | AD18: 11 | AE18: =AD18/AC18/24 -> 1.2222222 | AF18: 0.33333333 | AG18: 0.70833333 | AH18: {=SUM(IF((Table3[[#This Row],[TanggaK Produksi]]=Table5[Date])*('Daily Performance Monitoring '!$AF$2=Table5[Machine]),Table5[Downtime]))} -> 0 | AI18: =AG18-AF18-AH18 -> 0.375 | AJ18: 12 | AK18: =AJ18/AI18/24 -> 1.3333333 | AL18: 0.33333333 | AM18: 0.70833333 | AN18: {=SUM(IF((Table3[[#This Row],[TanggaK Produksi]]=Table5[Date])*('Daily Performance Monitoring '!$AL$2=Table5[Machine]),Table5[Downtime]))} -> 0 | AO18: =AM18-AL18-AN18 -> 0.375 | AP18: 10 | AQ18: =AP18/AO18/24 -> 1.1111111 | AR18: 0.33333333 | AS18: 0.70833333 | AT18: {=SUM(IF((Table3[[#This Row],[TanggaK Produksi]]=Table5[Date])*('Daily Performance Monitoring '!$AR$2=Table5[Machine]),Table5[Downtime]))} -> 0.013055556 | AU18: =AS18-AR18-AT18 -> 0.36194444 | AV18: 12 | AW18: =AV18/AU18/24 -> 1.3814275 | AX18: 0.33333333 | AY18: 0.70833333 | AZ18: {=SUM(IF((Table3[[#This Row],[TanggaK Produksi]]=Table5[Date])*('Daily Performance Monitoring '!$AX$2=Table5[Machine]),Table5[Downtime]))} -> 0.028333333 | BA18: =AY18-AX18-AZ18 -> 0.34666667 | BB18: 12 | BC18: =BB18/BA18/24 -> 1.4423077
A19: 45918 | B19: 0.33333333 | C19: 0.70833333 | D19: {=SUM(IF((Table3[[#This Row],[TanggaK Produksi]]=Table5[Date])*('Daily Performance Monitoring '!$B$2=Table5[Machine]),Table5[Downtime]))} -> 0 | E19: =C19-B19-D19 -> 0.375 | F19: 9 | G19: =F19/E19/24 -> 1 | H19: 0.33333333 | I19: 0.70833333 | J19: {=SUM(IF((Table3[[#This Row],[TanggaK Produksi]]=Table5[Date])*('Daily Performance Monitoring '!$H$2=Table5[Machine]),Table5[Downtime]))} -> 0 | K19: =I19-H19-J19 -> 0.375 | L19: 11 | M19: =L19/K19/24 -> 1.2222222 | N19: 0.33333333 | O19: 0.70833333 | P19: {=SUM(IF((Table3[[#This Row],[TanggaK Produksi]]=Table5[Date])*('Daily Performance Monitoring '!$N$2=Table5[Machine]),Table5[Downtime]))} -> 0.0033333333 | Q19: =O19-N19-P19 -> 0.37166667 | R19: 10 | S19: =R19/Q19/24 -> 1.1210762 | T19: 0.33333333 | U19: 0.70833333 | V19: {=SUM(IF((Table3[[#This Row],[TanggaK Produksi]]=Table5[Date])*('Daily Performance Monitoring '!$T$2=Table5[Machine]),Table5[Downtime]))} -> 0 | W19: =U19-T19-V19 -> 0.375 | X19: 11 | Y19: =X19/W19/24 -> 1.2222222 | Z19: 0.33333333 | AA19: 0.70833333 | AB19: {=SUM(IF((Table3[[#This Row],[TanggaK Produksi]]=Table5[Date])*('Daily Performance Monitoring '!$Z$2=Table5[Machine]),Table5[Downtime]))} -> 0 | AC19: =AA19-Z19-AB19 -> 0.375 | AD19: 10 | AE19: =AD19/AC19/24 -> 1.1111111 | AF19: 0.33333333 | AG19: 0.70833333 | AH19: {=SUM(IF((Table3[[#This Row],[TanggaK Produksi]]=Table5[Date])*('Daily Performance Monitoring '!$AF$2=Table5[Machine]),Table5[Downtime]))} -> 0 | AI19: =AG19-AF19-AH19 -> 0.375 | AJ19: 11 | AK19: =AJ19/AI19/24 -> 1.2222222 | AL19: 0.33333333 | AM19: 0.70833333 | AN19: {=SUM(IF((Table3[[#This Row],[TanggaK Produksi]]=Table5[Date])*('Daily Performance Monitoring '!$AL$2=Table5[Machine]),Table5[Downtime]))} -> 0 | AO19: =AM19-AL19-AN19 -> 0.375 | AP19: 10 | AQ19: =AP19/AO19/24 -> 1.1111111 | AR19: 0.33333333 | AS19: 0.70833333 | AT19: {=SUM(IF((Table3[[#This Row],[TanggaK Produksi]]=Table5[Date])*('Daily Performance Monitoring '!$AR$2=Table5[Machine]),Table5[Downtime]))} -> 0 | AU19: =AS19-AR19-AT19 -> 0.375 | AV19: 11 | AW19: =AV19/AU19/24 -> 1.2222222 | AX19: 0.33333333 | AY19: 0.70833333 | AZ19: {=SUM(IF((Table3[[#This Row],[TanggaK Produksi]]=Table5[Date])*('Daily Performance Monitoring '!$AX$2=Table5[Machine]),Table5[Downtime]))} -> 0 | BA19: =AY19-AX19-AZ19 -> 0.375 | BB19: 12 | BC19: =BB19/BA19/24 -> 1.3333333
